2025-06-24 16:03:51.550925: E external/local_xla/xla/stream_executor/cuda/cuda_fft.cc:485] Unable to register cuFFT factory: Attempting to register factory for plugin cuFFT when one has already been registered
2025-06-24 16:03:51.955654: E external/local_xla/xla/stream_executor/cuda/cuda_dnn.cc:8454] Unable to register cuDNN factory: Attempting to register factory for plugin cuDNN when one has already been registered
2025-06-24 16:03:52.078764: E external/local_xla/xla/stream_executor/cuda/cuda_blas.cc:1452] Unable to register cuBLAS factory: Attempting to register factory for plugin cuBLAS when one has already been registered
2025-06-24 16:03:57.692662: I tensorflow/core/platform/cpu_feature_guard.cc:210] This TensorFlow binary is optimized to use available CPU instructions in performance-critical operations.
To enable the following instructions: AVX2 AVX512F FMA, in other operations, rebuild TensorFlow with the appropriate compiler flags.
2025-06-24 16:26:04.625949: W tensorflow/compiler/tf2tensorrt/utils/py_utils.cc:38] TF-TRT Warning: Could not find TensorRT
2025-06-24 17:00:21.370800: E external/local_xla/xla/stream_executor/cuda/cuda_driver.cc:266] failed call to cuInit: CUDA_ERROR_MPS_CONNECTION_FAILED: MPS client failed to connect to the MPS control daemon or the MPS server
/lustre04/scratch/linah03/Autism/venvAutism/lib/python3.11/site-packages/keras/src/trainers/data_adapters/py_dataset_adapter.py:121: UserWarning: Your `PyDataset` class should call `super().__init__(**kwargs)` in its constructor. `**kwargs` can include `workers`, `use_multiprocessing`, `max_queue_size`. Do not pass these arguments to `fit()`, as they will be ignored.
  self._warn_if_super_not_called()
Traceback (most recent call last):
  File "/lustre04/scratch/linah03/Autism/cli/train.py", line 54, in <module>
  File "/lustre04/scratch/linah03/Autism/cli/train.py", line 42, in main
  File "/lustre04/scratch/linah03/Autism/venvAutism/lib/python3.11/site-packages/keras/src/utils/traceback_utils.py", line 122, in error_handler
  File "/cvmfs/soft.computecanada.ca/gentoo/2023/x86-64-v3/usr/lib/python3.11/contextlib.py", line 289, in helper
    return _GeneratorContextManager(func, args, kwds)
           ^^^^^^^^^^^^^^^^^^^^^^^^^^^^^^^^^^^^^^^^^^
MemoryError
